Workbook
Name \0: #N/A
Name \a: #N/A
Name LABEL_AIRE: '[1]MASTER Finishing Price List'!#REF!
Name NONAUXS_4: #REF!
Name Print_Area_MI: #REF!
Name TABLE: '[2]Piece Weight Calculation'!#REF!

Sheet SCOPE
B1: Scope of Tool
B3: For Estimator's use
B4: Perfect Bound and Saddle Stitched products
B5: Comparison tool to your estimating tool

Sheet USA & Canada
A1: L'Occitane, Inc.
A2: Regular Mailers
A3: 44950
A4: Revised 1/26/23
A5: Revised 2/13/23
A7: 2023 RFP
A8: Mailer Name | B8: MTH | C8: Country | D8: Contact Type | E8: OE | F8: Insert | G8: Size | H8: Ink | I8: Personalization | J8: Finishing / Mailing | K8: Data | L8: Cover /Text Paper | M8: Local Box | N8: Paper release / LDC | O8: Mail Vol | P8: IN HOME (MAILINGS) | Q8: Total Pricing | R8: Additional Ms | S8: Assumptions | T8: Pc Wt (#s) | U8: Non-Commingle Postage | V8: Commingle Postage
A9: MOTHER'S DAY | B9: APRIL | C9: USA | D9: 6p+4p Stitched Booklet Mailer | E9: NA | F9: NA | G9: 5.5 x 7.25 Finished | H9: 4cp/4cp | I9: Black address only + store location on mailing panel (4" area maximum) | J9: Stitch, tab (3), tray mail letter rate | K9: Presort Bundle (assumes one file in and out) | L9: 80# matte cover | O9: 500000 | P9: 44666 | Q9: 117479.68 | R9: 226.59294 | S9: Pricing assumes: 1 version included and common art files provided for both USA & Canada. PDF proofs and production ready files provided by client. Hard copy color proofs are $30/each. All data including store location provided in a single file per event. Canadian data and postage pricing assumes client is providing a presorted file. Please note all materials including paper are subject to market pricing and availability. | T9: 0.603 | U9: 0.328 | V9: 0.316
A10: MOTHER'S DAY | B10: APRIL | C10: CANADA | D10: 6p+4p Stitched Booklet Mailer | E10: NA | F10: NA | G10: 5.5 x 7.25 Finished | H10: 4cp/4cp | I10: Black address only + store location on mailing panel (4" area maximum) | J10: Stitch, tab (3), tray mail letter rate | K10: Presort Bundle (assumes one file in and out) | L10: 80# matte cover | O10: 90000 | P10: 44666 | Q10: 21146.343 | R10: 226.59294 | T10: 0.0603 | U10: 0.53193333 | V10: NA
A11: STAR ALMOND | B11: MAY | C11: USA | D11: Folded Self Mailer | E11: NA | F11: NA | G11: Bifold 7x10.5 flat 7x5.25 finished | H11: 4cp/4cp | I11: Black address only + store location on mailing panel (4" area maximum) | J11: Score, fold, tack glue, tray mail letter rate | K11: Presort Bundle (assumes one file in and out) | L11: 100# uncoated cvr | O11: 200000 | P11: 44690 | Q11: 23865.459 | R11: 109.95782 | S11: Pricing assumes: 1 version included and common art files provided for both USA & Canada. PDF proofs and production ready files provided by client. Hard copy color proofs are $30/each. All data including store location provided in a single file per event. Canadian data and postage pricing assumes client is providing a presorted file. Please note all materials including paper are subject to market pricing and availability. | T11: 0.0292 | U11: 0.32598 | V11: 0.316
A12: STAR ALMOND | B12: MAY | C12: CANADA | D12: Folded Self Mailer | E12: NA | F12: NA | G12: Bifold 7x10.5 flat 7x5.25 finished | H12: 4cp/4cp | I12: Black address only + store location on mailing panel (4" area maximum) | J12: Score, fold, tack glue, tray mail letter rate | K12: Presort Bundle (assumes one file in and out) | L12: 100# uncoated cvr | O12: 85000 | P12: 44690 | Q12: 10142.82 | R12: 109.95782 | T12: 0.0292 | U12: 0.53064706 | V12: NA
A13: SUMMER SALE POSTCARD | B13: JUNE | C13: USA | D13: Folded Self Mailer | E13: NA | F13: NA | G13: Trifold 7 x 15.625 flat 7x5.25 finished | H13: 4cp/4cp | I13: Black address only + store location on mailing panel (4" area maximum) | J13: Score, fold, tack glue, tray mail letter rate | K13: Presort Bundle (assumes one file in and out) | L13: 100# uncoated cvr | O13: 250000 | P13: 44718 | Q13: 40273.216 | R13: 152.33958 | S13: Pricing assumes: 1 version included and common art files provided for both USA & Canada. PDF proofs and production ready files provided by client. Hard copy color proofs are $30/each. All data including store location provided in a single file per event. Canadian data and postage pricing assumes client is providing a presorted file. Please note all materials including paper are subject to market pricing and availability. | T13: 0.0434 | U13: 0.327728 | V13: 0.315
A14: SUMMER SALE POSTCARD | B14: JUNE | C14: CANADA | D14: Folded Self Mailer | E14: NA | F14: NA | G14: Trifold 7 x 15.625 flat 7x5.25 finished | H14: 4cp/4cp | I14: Black address only + store location on mailing panel (4" area maximum) | J14: Score, fold, tack glue, tray mail letter rate | K14: Presort Bundle (assumes one file in and out) | L14: 100# uncoated cvr | O14: 50000 | P14: 44718 | Q14: 8054.6433 | R14: 152.33958 | T14: 0.0434 | U14: 0.5346 | V14: NA
A15: STAR INGREDIENTS verbena classic/mint | B15: JULY | C15: USA | D15: Postcard | E15: NA | F15: NA | G15: 8 x 6 | H15: 4cp/4cp | I15: Black address only + store location on mailing panel (4" area maximum) | J15: Trim, tack glue, tray mail letter rate | K15: Presort Bundle (assumes one file in and out) | L15: 100# uncoated cvr | O15: 200000 | P15: 44734 | Q15: 14502.247 | R15: 65.280653 | S15: Pricing assumes: 1 version included and common art files provided for both USA & Canada. PDF proofs and production ready files provided by client. Hard copy color proofs are $30/each. All data including store location provided in a single file per event. Canadian data and postage pricing assumes client is providing a presorted file. Please note all materials including paper are subject to market pricing and availability. | T15: 0.019 | U15: 0.32397 | V15: 0.316
A16: STAR INGREDIENTS verbena classic/mint | B16: JULY | C16: CANADA | D16: Postcard | E16: NA | F16: NA | G16: 8 x 6 | H16: 4cp/4cp | I16: Black address only + store location on mailing panel (4" area maximum) | J16: Trim, tack glue, tray mail letter rate | K16: Presort Bundle (assumes one file in and out) | L16: 100# uncoated cvr | O16: 70000 | P16: 44734 | Q16: 5075.7863 | R16: 65.280653 | T16: 0.019 | U16: 0.53185714 | V16: NA
A17: DIVINE SKINCARE/BEST SELLERS | B17: AUGUST | C17: USA | D17: Folded Self Mailer | E17: NA | F17: NA | G17: Trifold 7 x 15.625 flat 7x5.25 finished | H17: 4cp/4cp | I17: Black address only + store location on mailing panel (4" area maximum) | J17: Score, fold, tack glue, tray mail letter rate | K17: Presort Bundle (assumes one file in and out) | L17: 100# uncoated cvr | O17: 250000 | P17: 44769 | Q17: 40273.216 | R17: 152.33958 | S17: Pricing assumes: 1 version included and common art files provided for both USA & Canada. PDF proofs and production ready files provided by client. Hard copy color proofs are $30/each. All variable data includes store location provided in a single file per event. Canadian data and postage pricing assumes client is providing a presorted file. Please note all materials including paper are subject to market pricing and availability. | T17: 0.0434 | U17: 0.327728 | V17: 0.315
A18: DIVINE SKINCARE/BEST SELLERS | B18: AUGUST | C18: CANADA | D18: Folded Self Mailer | E18: NA | F18: NA | G18: Trifold 7 x 15.625 flat 7x5.25 finished | H18: 4cp/4cp | I18: Black address only + store location on mailing panel (4" area maximum) | J18: Score, fold, tack glue, tray mail letter rate | K18: Presort Bundle (assumes one file in and out) | L18: 100# uncoated cvr | O18: 50000 | P18: 44769 | Q18: 8054.6433 | R18: 152.33958 | T18: 0.0434 | U18: 0.5346
A19: PRECIOUS RELAUNCH | B19: SEPTEMBER | C19: USA | D19: Folded Self Mailer | E19: NA | F19: NA | G19: Trifold 7 x 15.625 flat 7x5.25 finished | H19: 4cp/4cp | I19: Black address only + store location on mailing panel (4" area maximum) | J19: Score, fold, tack glue, tray mail letter rate | K19: Presort Bundle (assumes one file in and out) | L19: 100# uncoated cvr | O19: 340000 | P19: 44804 | Q19: 53878.324 | R19: 152.35872 | S19: Pricing assumes: 1 version included and common art files provided for both USA & Canada. PDF proofs and production ready files provided by client. Hard copy color proofs are $30/each. All data includes store location provided in a single file per event. Please note all materials including paper are subject to market pricing and availability. | T19: 0.0434 | U19: 0.32669706 | V19: 0.315
A20: PRECIOUS RELAUNCH | B20: SEPTEMBER | C20: CANADA | D20: Folded Self Mailer | E20: NA | F20: NA | G20: Trifold 7 x 15.625 flat 7x5.25 finished | H20: 4cp/4cp | I20: Black address only + store location on mailing panel (4" area maximum) | J20: Score, fold, tack glue, tray mail letter rate | K20: Presort Bundle (assumes one file in and out) | L20: 100# uncoated cvr | O20: 90000 | P20: 44804 | Q20: 14261.909 | R20: 152.35872 | T20: 0.0434 | U20: 0.53033333 | V20: NA
A21: CUSTOMER APPRECIATION | B21: SEPTEMBER | C21: USA | D21: Postcard | E21: NA | F21: NA | G21: 8 x 6 | H21: 4cp/4cp | I21: Black address only + store location on mailing panel (4" area maximum) | J21: Trim, tack glue, tray mail letter rate | K21: Presort Bundle (assumes one file in and out) | L21: 100# Anthem Matte cover FSC | O21: 600000 | P21: 44818 | Q21: 38817.466 | R21: 62.255456 | S21: Pricing assumes: 1 version included and common art files provided for both USA & Canada. PDF proofs and production ready files provided by client. Hard copy color proofs are $30/each. All data includes store location provided in a single file per event. Please note all materials including paper are subject to market pricing and availability. | T21: 0.019 | U21: 0.31754833 | V21: 0.312
A22: CUSTOMER APPRECIATION | B22: SEPTEMBER | C22: CANADA | D22: Postcard | E22: NA | F22: NA | G22: 8 x 6 | H22: 4cp/4cp | I22: Black address only + store location on mailing panel (4" area maximum) | J22: Trim, tack glue, tray mail letter rate | K22: Presort Bundle (assumes one file in and out) | L22: 100# Anthem Matte cover FSC | O22: 200000 | P22: 44818 | Q22: 12939.155 | R22: 62.255456 | T22: 0.019 | U22: 0.5274 | V22: NA
A23: PRE-HOLIDAY | B23: OCTOBER | C23: USA | D23: Folded Self Mailer | E23: NA | F23: NA | G23: Trifold 7 x 15.625 flat 7x5.25 finished | H23: 4cp/4cp | I23: Black address only + store location on mailing panel (4" area maximum) | J23: Score, fold, tack glue, tray mail letter rate | K23: Presort Bundle (assumes one file in and out) | L23: 100# uncoated cvr | O23: 400000 | P23: 44839 | Q23: 62998.614 | R23: 62.255456 | S23: Pricing assumes: 1 version included and common art files provided for both USA & Canada. PDF proofs and production ready files provided by client. Hard copy color proofs are $30/each. All data including store location provided in a single file per event. Canadian data and postage pricing assumes client is providing a presorted file. Please note all materials including paper are subject to market pricing and availability. | T23: 0.0434 | U23: 0.3265525 | V23: 0.315
A24: PRE-HOLIDAY | B24: OCTOBER | C24: CANADA | D24: Folded Self Mailer | E24: NA | F24: NA | G24: Trifold 7 x 15.625 flat 7x5.25 finished | H24: 4cp/4cp | I24: Black address only + store location on mailing panel (4" area maximum) | J24: Score, fold, tack glue, tray mail letter rate | K24: Presort Bundle (assumes one file in and out) | L24: 100# uncoated cvr | O24: 110000 | P24: 44839 | Q24: 17324.619 | R24: 62.255456 | T24: 0.0434 | U24: 0.52992727 | V24: NA
A25: HOLIDAY 1 CATALOG | B25: NOVEMBER | C25: USA | D25: Envelope Package with Catalog (20 Pg + 4pg) + 2pg Insert | E25: 6x9 Booklet OE (flap on long side*), closed faced, 4CP outside, heavy coverage, bleeds, knock out for address on flap seal side, 7pt uncoated (100# opaque text)** | F25: 2pg 5.5 x 7.25, 4/4, with scent seal | G25: 5.5 x 7.25 Finished | H25: 4cp/4cp | I25: Black address only + store location on mailing panel (4" area maximum) | J25: Stitch book,apply scent seal to 2pg card (customer-supplied) Insert 2 into OE, image black address only, no match, tray mail flat | K25: Presort Bundle (assumes one file in and out) | L25: Mohawk Uncoated Via Smooth 80# Cover | O25: 250000 | P25: 44868 | Q25: 222771.68 | R25: 873.72214 | S25: Pricing assumes: 1 version included and common art files provided for both USA & Canada. PDF proofs and production ready files provided by client. Hard copy color proofs are $30/each. Scent Seal provided to Quad as an labelaire on a roll All data includes store location provided in a single file per event. Canadian data and postage pricing assumes client is providing a presorted file. Please note all materials including paper are subject to market pricing and availability. | T25: 0.2053 | U25: 0.360488 | V25: 0.331
A26: HOLIDAY 1 CATALOG | B26: NOVEMBER | C26: CANADA | D26: Envelope Package with Catalog (20 Pg + 4pg) + 2pg Insert | E26: 6x9 Booklet OE (flap on long side*), closed faced, 4CP outside, heavy coverage, bleeds, knock out for address on flap seal side, 7pt uncoated (100# opaque text)** | F26: 2pg 5.5 x 7.25, 4/4, with scent seal | G26: 5.5 x 7.25 Finished | H26: 4cp/4cp | I26: Black address only + store location on mailing panel (4" area maximum) | J26: Stitch book,apply scent seal to 2pg card (customer-supplied) Insert 2 into OE, image black address only, no match, tray mail flat | K26: Presort Bundle (assumes one file in and out) | L26: Mohawk Uncoated Via Smooth 80# Cover | O26: 50000 | P26: 44868 | Q26: 44554.337 | R26: 873.72214 | S26: Pricing assumes: 1 version included and common art files provided for both USA & Canada. PDF proofs and production ready files provided by client. Hard copy color proofs are $30/each. Scent Seal provided to Quad as an labelaire on a roll All data includes store location provided in a single file per event. Canadian data and postage pricing assumes client is providing a presorted file. Please note all materials including paper are subject to market pricing and availability. | T26: 0.2053 | U26: 0.96442 | V26: NA
A27: HOLIDAY 1 CATALOG | B27: NOVEMBER | C27: USA & CANADA | D27: Scented Label RCR Clear BOPP/Clear BOPP Permanent Label Encapsulated Fragrance Snap & Burst | E27: NA | F27: NA | G27: 2x2 Finished | H27: Clear | I27: none | J27: NA | K27: NA | L27: Stock #249 2 Clear BOPP W/Operm Adhesive/ Stock #249 2 Clear BOPP W/Operm Adhesive | O27: 300000 | P27: 44868 | Q27: 18415.755 | R27: 61.38585 | S27: Pricing assumes: Fragrence oil is supplied by the client to vendor for encapsulation. Schedule TBD depending on delivery of oil. Pricing valid for 30 days. Please note all materials are subject to market pricing and availability.
A28: BF/CM POSTCARD | B28: NOVEMBER | C28: USA | D28: Postcard | E28: NA | F28: NA | G28: 8 x 6 | H28: 4cp/4cp | I28: Black address only + store location on mailing panel (4" area maximum) | J28: Trim, tack glue, tray mail letter rate | K28: Presort Bundle (assumes one file in and out) | L28: 100# Anthem Matte cover FSC | O28: 1000000 | P28: 44888 | Q28: 60807.572 | R28: 59.210155 | S28: Pricing assumes: 1 version included and common art files provided for both USA & Canada. PDF proofs and production ready files provided by client. Hard copy color proofs are $30/each. All data including store location provided in a single file per event. Canadian data and postage pricing assumes client is providing a presorted file. Please note all materials including paper are subject to market pricing and availability. | T28: 0.019 | U28: 0.307575 | V28: 0.312
A29: BF/CM POSTCARD | B29: NOVEMBER | C29: CANADA | D29: Postcard | E29: NA | F29: NA | G29: 8 x 6 | H29: 4cp/4cp | I29: Black address only + store location on mailing panel (4" area maximum) | J29: Trim, tack glue, tray mail letter rate | K29: Presort Bundle (assumes one file in and out) | L29: 100# Anthem Matte cover FSC | O29: 200000 | P29: 44888 | Q29: 12161.514 | R29: 59.210155 | T29: 0.019 | U29: 0.5274 | V29: NA
A30: HOLIDAY 2 | B30: DECEMBER | C30: USA | D30: Folded Self Mailer | E30: NA | F30: NA | G30: Trifold 7 x 15.625 flat 7x5.25 finished | H30: 4cp/4cp | I30: Black address only + store location on mailing panel (4" area maximum) | J30: Score, fold, tack glue, tray mail letter rate | K30: Presort Bundle (assumes one file in and out) | L30: 100# uncoated cvr | O30: 200000 | P30: 44897 | Q30: 32285.24 | R30: 152.33958 | S30: Pricing assumes: 1 version included and common art files provided for both USA & Canada. PDF proofs and production ready files provided by client. Hard copy color proofs are $30/each. All data including store location provided in a single file per event. Canadian data and postage pricing assumes client is providing a presorted file. Please note all materials including paper are subject to market pricing and availability. | T30: 0.0434 | U30: 0.328775 | V30: 0.318
A31: HOLIDAY 2 | B31: DECEMBER | C31: CANADA | D31: Folded Self Mailer | E31: NA | F31: NA | G31: Trifold 7 x 15.625 flat 7x5.25 finished | H31: 4cp/4cp | I31: Black address only + store location on mailing panel (4" area maximum) | J31: Score, fold, tack glue, tray mail letter rate | K31: Presort Bundle (assumes one file in and out) | L31: 100# uncoated cvr | O31: 100000 | P31: 44897 | Q31: 16142.62 | R31: 152.33958 | T31: 0.0434 | U31: 0.53002 | V31: NA
A32: WINTER SALE | B32: JANUARY | C32: USA | D32: Postcard | E32: NA | F32: NA | G32: 8 x 6 | H32: 4cp/4cp | I32: Black address only + store location on mailing panel (4" area maximum) | J32: Trim, tack glue, tray mail letter rate | K32: Presort Bundle (assumes one file in and out) | L32: 100# uncoated cvr | O32: 120000 | P32: 44921 | Q32: 8814.0072 | R32: 61.966198 | S32: Pricing assumes: 1 version included and common art files provided for both USA & Canada. PDF proofs and production ready files provided by client. Hard copy color proofs are $30/each. All data including store location provided in a single file per event. Please note all materials including paper are subject to market pricing and availability. | T32: 0.019 | U32: 0.32649167 | V32: 0.316
A33: WINTER SALE | B33: JANUARY | C33: CANADA | D33: Postcard | E33: NA | F33: NA | G33: 8 x 6 | H33: 4cp/4cp | I33: Black address only + store location on mailing panel (4" area maximum) | J33: Trim, tack glue, tray mail letter rate | K33: Presort Bundle (assumes one file in and out) | L33: 100# uncoated cvr | O33: 50000 | P33: 44921 | Q33: 3672.503 | R33: 61.966198 | T33: 0.019 | U33: 0.5346 | V33: NA
A34: SHEA IMMORTELLE ANTI-AGING | B34: FEBRUARY | C34: USA | D34: Folded Self Mailer | E34: NA | F34: NA | G34: Bifold w/ 3" Flap 8 x 15 flat 8x6 finished | H34: 4cp/4cp | I34: Black address only + store location on mailing panel (4" area maximum) | J34: Score, fold, tack glue, tray mail letter rate | K34: Presort Bundle (assumes one file in and out) | L34: 100# uncoated cvr | O34: 190000 | P34: 44937 | Q34: 23222.797 | R34: 109.95782 | S34: Pricing assumes: 1 version included and common art files provided for both USA & Canada. PDF proofs and production ready files provided by client. Hard copy color proofs are $30/each. All data including store location provided in a single file per event. Canadian data and postage pricing assumes client is providing a presorted file. Please note all materials including paper are subject to market pricing and availability. | T34: 0.0476 | U34: 0.32976316 | V34: 0.318
A35: SHEA IMMORTELLE ANTI-AGING | B35: FEBRUARY | C35: CANADA | D35: Folded Self Mailer | E35: NA | F35: NA | G35: Bifold w/ 3" Flap 8 x 15 flat 8x6 finished | H35: 4cp/4cp | I35: Black address only + store location on mailing panel (4" area maximum) | J35: Score, fold, tack glue, tray mail letter rate | K35: Presort Bundle (assumes one file in and out) | L35: 100# uncoated cvr | O35: 85000 | P35: 44937 | Q35: 10389.146 | R35: 109.95782 | T35: 0.0476 | U35: 0.53064706 | V35: NA
A36: FACECARE - best lab in the world is nature | B36: FEBRUARY | C36: USA | D36: Folded Self Mailer | E36: NA | F36: NA | G36: Trifold 7 x 15.625 flat 7x5.25 finished | H36: 4cp/4cp | I36: Black address only + store location on mailing panel (4" area maximum) | J36: Score, fold, tack glue, tray mail letter rate | K36: Presort Bundle (assumes one file in and out) | L36: 100# uncoated cvr | O36: 280000 | P36: 44972 | Q36: 44869.138 | R36: 152.28939 | S36: Pricing assumes: 1 version included and common art files provided for both USA & Canada. PDF proofs and production ready files provided by client. Hard copy color proofs are $30/each. All variable data including store location provided in a single file per event. Canadian data and postage pricing assumes client is providing a presorted file. Please note all materials including paper are subject to market pricing and availability. | T36: 0.0434 | U36: 0.32673571 | V36: 0.315
A37: FACECARE - best lab in the world is nature | B37: FEBRUARY | C37: CANADA | D37: Folded Self Mailer | E37: NA | F37: NA | G37: Trifold 7 x 15.625 flat 7x5.25 finished | H37: 4cp/4cp | I37: Black address only + store location on mailing panel (4" area maximum) | J37: Score, fold, tack glue, tray mail letter rate | K37: Presort Bundle (assumes one file in and out) | L37: 100# uncoated cvr | O37: 50000 | P37: 44972 | Q37: 8012.3461 | R37: 152.28939 | T37: 0.0434 | U37: 0.5346 | V37: NA
A38: FRIENDS & FAMILY | B38: MARCH | C38: USA | D38: Postcard | E38: NA | F38: NA | G38: 8 x 6 | H38: 4cp/4cp | I38: Black address only + store location on mailing panel (4" area maximum) | J38: Trim, tack glue, tray mail letter rate | K38: Presort Bundle (assumes one file in and out) | L38: 100# Anthem Matte cover FSC | O38: 545000 | P38: 45014 | Q38: 33524.825 | R38: 58.892962 | S38: Pricing assumes: 1 version included and common art files provided for both USA & Canada. PDF proofs and production ready files provided by client. Hard copy color proofs are $30/each. All variable data including store location provided in a single file per event. Canadian data and postage pricing assumes client is providing a presorted file. Please note all materials including paper are subject to market pricing and availability. | T38: 0.019 | U38: 0.87176 | V38: 0.312
A39: FRIENDS & FAMILY | B39: MARCH | C39: CANADA | D39: Postcard | E39: NA | F39: NA | G39: 8 x 6 | H39: 4cp/4cp | I39: Black address only + store location on mailing panel (4" area maximum) | J39: Trim, tack glue, tray mail letter rate | K39: Presort Bundle (assumes one file in and out) | L39: 100# Anthem Matte cover FSC | O39: 200000 | P39: =P38 -> 45014 | Q39: 12302.688 | R39: 58.892962 | T39: 0.019 | U39: 0.5274 | V39: NA
O40: =SUM(O9:O39) -> 7105000
E41: *Please Note - flap must be on the long side for machine inserting
...

Sheet Price Schedule (2)
A1: TRANSACTIONAL PRICING | R1: What is the Pricing Level? | S1: Use Out The Door Levels | AI1: MR % | AK1: Run/M % | BA1: Price List Attributes | BB1: MR | BC1: Run
A2: Price Schedule - Confidential | S2: 0.08 | U2: Surcharge | AA2: =IF(ISNUMBER(SEARCH("%",S1)),1,0)*AI2 -> 0 | AC2: =IF(ISNUMBER(SEARCH("%",S1)),1,0)*AK2 -> 0 | AI2: 0.2 | AK2: 0.2 | BA2: Use Benchmark Levels | BB2: 11 | BC2: 13
A3: DMC Space | S3: *all rates have been increased by the 8% surcharge | BA3: Use Out The Door Levels | BB3: 15 | BC3: 17
A4: 50# - 12pt | AI4: DO NOT CHANGE | BA4: Use Floor Levels | BB4: 19 | BC4: 21
BA5: % Adjusted From Benchmark | BB5: 27 | BC5: 29
AI6: PROPOSED | AM6: % FROM BENCHMARK | BA6: % Adjusted From Out The Door | BB6: 32 | BC6: 34
K7: BENCHMARK | O7: OUT THE DOOR | S7: FLOOR | W7: MANUAL OVERRIDE | AA7: BM w/ % Change | AE7: OTD w/ % Change | BA7: *** Already tied to $-List - just add to LIST in T1
A9: IMAGING FORMAT | E9: per pg (y or n) | K9: EACH | O9: =K9 -> EACH | Q9: =M9 | S9: =K9 -> EACH | U9: =M9 | W9: =K9 -> EACH | Y9: =M9 | AA9: =K9 -> EACH | AC9: =M9 | AE9: =O9 -> EACH | AG9: =M9 | AI9: =K9 -> EACH | AK9: =M9 | AM9: =K9 -> EACH | AO9: =M9
A10: COMMERCIAL
A11: PDFX1A-DOWNLOAD, POST, PLATE per page | E11: y | K11: 10 | M11: 0 | O11: 8 | Q11: 0 | S11: 4.75 | U11: 0 | AA11: =$K11*(1+$AI$2) -> 12 | AC11: =$M11*(1+$AK$2) -> 0 | AE11: =$O11*(1+$AI$2) -> 9.6 | AG11: =$Q11*(1+$AK$2) -> 0 | AI11: =IF(ISBLANK(W11),VLOOKUP(A11,A11:AG11,VLOOKUP($S$1,'Price Schedule (2)'!$BA$2:$BC$6,2,FALSE),FALSE),W11) -> 8 | AK11: =IF(ISBLANK(Y11),VLOOKUP(A11,A11:AG11,VLOOKUP($S$1,'Price Schedule (2)'!$BA$2:$BC$6,3,FALSE),FALSE),Y11) -> 0 | AM11: =IF(AND(K11=0,W11=0),0,IF(K11=0,"BM is $0",(AI11-K11)/K11)) -> -0.2 | AO11: =IF(AND(M11=0,Y11=0),0,IF(M11=0,"BM is $0",(AK11-M11)/M11)) -> 0
A12: DIGITAL BLUE LINES per page | E12: y | K12: 1.5 | M12: 0 | O12: 1 | Q12: 0 | S12: 0.5 | U12: 0 | AA12: =$K12*(1+$AI$2) -> 1.8 | AC12: =$M12*(1+$AK$2) -> 0 | AE12: =$O12*(1+$AI$2) -> 1.2 | AG12: =$Q12*(1+$AK$2) -> 0 | AI12: =IF(ISBLANK(W12),VLOOKUP(A12,A12:AG12,VLOOKUP($S$1,'Price Schedule (2)'!$BA$2:$BC$6,2,FALSE),FALSE),W12) -> 1 | AK12: =IF(ISBLANK(Y12),VLOOKUP(A12,A12:AG12,VLOOKUP($S$1,'Price Schedule (2)'!$BA$2:$BC$6,3,FALSE),FALSE),Y12) -> 0 | AM12: =IF(AND(K12=0,W12=0),0,IF(K12=0,"BM is $0",(AI12-K12)/K12)) -> -0.33333333 | AO12: =IF(AND(M12=0,Y12=0),0,IF(M12=0,"BM is $0",(AK12-M12)/M12)) -> 0
A13: CONTRACT PROOFS per page | E13: y | K13: 15 | M13: 0 | O13: 15 | Q13: 0 | S13: 6.25 | U13: 0 | AA13: =$K13*(1+$AI$2) -> 18 | AC13: =$M13*(1+$AK$2) -> 0 | AE13: =$O13*(1+$AI$2) -> 18 | AG13: =$Q13*(1+$AK$2) -> 0 | AI13: =IF(ISBLANK(W13),VLOOKUP(A13,A13:AG13,VLOOKUP($S$1,'Price Schedule (2)'!$BA$2:$BC$6,2,FALSE),FALSE),W13) -> 15 | AK13: =IF(ISBLANK(Y13),VLOOKUP(A13,A13:AG13,VLOOKUP($S$1,'Price Schedule (2)'!$BA$2:$BC$6,3,FALSE),FALSE),Y13) -> 0 | AM13: =IF(AND(K13=0,W13=0),0,IF(K13=0,"BM is $0",(AI13-K13)/K13)) -> 0 | AO13: =IF(AND(M13=0,Y13=0),0,IF(M13=0,"BM is $0",(AK13-M13)/M13)) -> 0
A14: CONTRACT PROOFS - CVR ONLY per page | E14: y | K14: 15 | M14: 0 | O14: 15 | Q14: 0 | S14: 6.25 | U14: 0 | AA14: =$K14*(1+$AI$2) -> 18 | AC14: =$M14*(1+$AK$2) -> 0 | AE14: =$O14*(1+$AI$2) -> 18 | AG14: =$Q14*(1+$AK$2) -> 0 | AI14: =IF(ISBLANK(W14),VLOOKUP(A14,A14:AG14,VLOOKUP($S$1,'Price Schedule (2)'!$BA$2:$BC$6,2,FALSE),FALSE),W14) -> 15 | AK14: =IF(ISBLANK(Y14),VLOOKUP(A14,A14:AG14,VLOOKUP($S$1,'Price Schedule (2)'!$BA$2:$BC$6,3,FALSE),FALSE),Y14) -> 0 | AM14: =IF(AND(K14=0,W14=0),0,IF(K14=0,"BM is $0",(AI14-K14)/K14)) -> 0 | AO14: =IF(AND(M14=0,Y14=0),0,IF(M14=0,"BM is $0",(AK14-M14)/M14)) -> 0
A15: NON-CONTRACT PROOFS per page | E15: y | K15: 10 | M15: 0 | O15: 10 | Q15: 0 | S15: 5 | U15: 0 | AA15: =$K15*(1+$AI$2) -> 12 | AC15: =$M15*(1+$AK$2) -> 0 | AE15: =$O15*(1+$AI$2) -> 12 | AG15: =$Q15*(1+$AK$2) -> 0 | AI15: =IF(ISBLANK(W15),VLOOKUP(A15,A15:AG15,VLOOKUP($S$1,'Price Schedule (2)'!$BA$2:$BC$6,2,FALSE),FALSE),W15) -> 10 | AK15: =IF(ISBLANK(Y15),VLOOKUP(A15,A15:AG15,VLOOKUP($S$1,'Price Schedule (2)'!$BA$2:$BC$6,3,FALSE),FALSE),Y15) -> 0 | AM15: =IF(AND(K15=0,W15=0),0,IF(K15=0,"BM is $0",(AI15-K15)/K15)) -> 0 | AO15: =IF(AND(M15=0,Y15=0),0,IF(M15=0,"BM is $0",(AK15-M15)/M15)) -> 0
A16: IMPRESS PROOF | E16: n | K16: 80 | M16: 0 | O16: 40 | Q16: 0 | S16: 30 | U16: 0 | AA16: =$K16*(1+$AI$2) -> 96 | AC16: =$M16*(1+$AK$2) -> 0 | AE16: =$O16*(1+$AI$2) -> 48 | AG16: =$Q16*(1+$AK$2) -> 0 | AI16: =IF(ISBLANK(W16),VLOOKUP(A16,A16:AG16,VLOOKUP($S$1,'Price Schedule (2)'!$BA$2:$BC$6,2,FALSE),FALSE),W16) -> 40 | AK16: =IF(ISBLANK(Y16),VLOOKUP(A16,A16:AG16,VLOOKUP($S$1,'Price Schedule (2)'!$BA$2:$BC$6,3,FALSE),FALSE),Y16) -> 0 | AM16: =IF(AND(K16=0,W16=0),0,IF(K16=0,"BM is $0",(AI16-K16)/K16)) -> -0.5 | AO16: =IF(AND(M16=0,Y16=0),0,IF(M16=0,"BM is $0",(AK16-M16)/M16)) -> 0
A17: N/A | E17: n | K17: 0 | M17: 0 | O17: 0 | Q17: 0 | S17: 0 | U17: 0 | AA17: =$K17*(1+$AI$2) -> 0 | AC17: =$M17*(1+$AK$2) -> 0 | AE17: =$O17*(1+$AI$2) -> 0 | AG17: =$Q17*(1+$AK$2) -> 0 | AI17: =IF(ISBLANK(W17),VLOOKUP(A17,A17:AG17,VLOOKUP($S$1,'Price Schedule (2)'!$BA$2:$BC$6,2,FALSE),FALSE),W17) -> 0 | AK17: =IF(ISBLANK(Y17),VLOOKUP(A17,A17:AG17,VLOOKUP($S$1,'Price Schedule (2)'!$BA$2:$BC$6,3,FALSE),FALSE),Y17) -> 0 | AM17: =IF(AND(K17=0,W17=0),0,IF(K17=0,"BM is $0",(AI17-K17)/K17)) -> 0 | AO17: =IF(AND(M17=0,Y17=0),0,IF(M17=0,"BM is $0",(AK17-M17)/M17)) -> 0
A18: DIRECT MAIL
A19: CUSTOMER CONTRACT COLOR PROOFS per page | E19: y | K19: 50 | M19: 0 | O19: 35 | Q19: 0 | S19: 20 | U19: 0
A20: VARIABLE IMAGING template design | E20: n | K20: 350 | M20: 0 | O20: 250 | Q20: 0 | S20: 100 | U20: 0 | AA20: =$K20*(1+$AI$2) -> 420 | AC20: =$M20*(1+$AK$2) -> 0 | AE20: =$O20*(1+$AI$2) -> 300 | AG20: =$Q20*(1+$AK$2) -> 0 | AI20: =IF(ISBLANK(W20),VLOOKUP(A20,A20:AG20,VLOOKUP($S$1,'Price Schedule (2)'!$BA$2:$BC$6,2,FALSE),FALSE),W20) -> 250 | AK20: =IF(ISBLANK(Y20),VLOOKUP(A20,A20:AG20,VLOOKUP($S$1,'Price Schedule (2)'!$BA$2:$BC$6,3,FALSE),FALSE),Y20) -> 0 | AM20: =IF(AND(K20=0,W20=0),0,IF(K20=0,"BM is $0",(AI20-K20)/K20)) -> -0.28571429 | AO20: =IF(AND(M20=0,Y20=0),0,IF(M20=0,"BM is $0",(AK20-M20)/M20)) -> 0
A21: Alteration files to be billed at base price plus 50%. | AA21: =$K21*(1+$AI$2) -> 0 | AC21: =$M21*(1+$AK$2) -> 0 | AE21: =$O21*(1+$AI$2) -> 0 | AG21: =$Q21*(1+$AK$2) -> 0 | AI21: =IF(ISBLANK(W21),VLOOKUP(A21,A21:AG21,VLOOKUP($S$1,'Price Schedule (2)'!$BA$2:$BC$6,2,FALSE),FALSE),W21) -> 0 | AK21: =IF(ISBLANK(Y21),VLOOKUP(A21,A21:AG21,VLOOKUP($S$1,'Price Schedule (2)'!$BA$2:$BC$6,3,FALSE),FALSE),Y21) -> 0 | AM21: =IF(AND(K21=0,W21=0),0,IF(K21=0,"BM is $0",(AI21-K21)/K21)) -> 0 | AO21: =IF(AND(M21=0,Y21=0),0,IF(M21=0,"BM is $0",(AK21-M21)/M21)) -> 0
A27: DIGITAL PRESSES (A4 Size - One Side - Includes Paper) | K27: MAKE-READY | M27: PER/M | O27: =K27 -> MAKE-READY | Q27: =M27 -> PER/M | S27: =K27 -> MAKE-READY | U27: =M27 -> PER/M | W27: =K27 -> MAKE-READY | Y27: =M27 -> PER/M | AA27: =K27 -> MAKE-READY | AC27: =M27 -> PER/M | AE27: =O27 -> MAKE-READY | AG27: =M27 -> PER/M | AI27: =K27 -> MAKE-READY | AK27: =M27 -> PER/M | AM27: =K27 -> MAKE-READY | AO27: =M27 -> PER/M
A28: T-SERIES - Inkjet
A29: 0c Print 50lb - 60lb text | K29: 50 | M29: 3 | O29: 35 | Q29: 3 | S29: 0 | U29: 2 | AA29: =$K29*(1+$AI$2) -> 60 | AC29: =$M29*(1+$AK$2) -> 3.6 | AE29: =$O29*(1+$AI$2) -> 42 | AG29: =$Q29*(1+$AK$2) -> 3.6 | AI29: =IF(ISBLANK(W29),VLOOKUP(A29,A29:AG29,VLOOKUP($S$1,'Price Schedule (2)'!$BA$2:$BC$6,2,FALSE),FALSE),W29) -> 35 | AK29: =IF(ISBLANK(Y29),VLOOKUP(A29,A29:AG29,VLOOKUP($S$1,'Price Schedule (2)'!$BA$2:$BC$6,3,FALSE),FALSE),Y29) -> 3 | AM29: =IF(AND(K29=0,W29=0),0,IF(K29=0,"BM is $0",(AI29-K29)/K29)) -> -0.3 | AO29: =IF(AND(M29=0,Y29=0),0,IF(M29=0,"BM is $0",(AK29-M29)/M29)) -> 0
A30: 1c Print 50lb - 60lb text, light ink (<10%) | K30: 50 | M30: 10 | O30: 35 | Q30: 10 | S30: 0 | U30: 8 | AA30: =$K30*(1+$AI$2) -> 60 | AC30: =$M30*(1+$AK$2) -> 12 | AE30: =$O30*(1+$AI$2) -> 42 | AG30: =$Q30*(1+$AK$2) -> 12 | AI30: =IF(ISBLANK(W30),VLOOKUP(A30,A30:AG30,VLOOKUP($S$1,'Price Schedule (2)'!$BA$2:$BC$6,2,FALSE),FALSE),W30) -> 35 | AK30: =IF(ISBLANK(Y30),VLOOKUP(A30,A30:AG30,VLOOKUP($S$1,'Price Schedule (2)'!$BA$2:$BC$6,3,FALSE),FALSE),Y30) -> 10 | AM30: =IF(AND(K30=0,W30=0),0,IF(K30=0,"BM is $0",(AI30-K30)/K30)) -> -0.3 | AO30: =IF(AND(M30=0,Y30=0),0,IF(M30=0,"BM is $0",(AK30-M30)/M30)) -> 0
A31: 1c Print 50lb - 60lb text, medium ink (10% - 25%) | K31: 50 | M31: 15 | O31: 35 | Q31: 15 | S31: 0 | U31: 9 | AA31: =$K31*(1+$AI$2) -> 60 | AC31: =$M31*(1+$AK$2) -> 18 | AE31: =$O31*(1+$AI$2) -> 42 | AG31: =$Q31*(1+$AK$2) -> 18 | AI31: =IF(ISBLANK(W31),VLOOKUP(A31,A31:AG31,VLOOKUP($S$1,'Price Schedule (2)'!$BA$2:$BC$6,2,FALSE),FALSE),W31) -> 35 | AK31: =IF(ISBLANK(Y31),VLOOKUP(A31,A31:AG31,VLOOKUP($S$1,'Price Schedule (2)'!$BA$2:$BC$6,3,FALSE),FALSE),Y31) -> 15 | AM31: =IF(AND(K31=0,W31=0),0,IF(K31=0,"BM is $0",(AI31-K31)/K31)) -> -0.3 | AO31: =IF(AND(M31=0,Y31=0),0,IF(M31=0,"BM is $0",(AK31-M31)/M31)) -> 0
A32: 4c Print 50lb - 60lb text, light ink (<10%) | K32: 50 | M32: 20 | O32: 35 | Q32: 20 | S32: 0 | U32: 13 | AA32: =$K32*(1+$AI$2) -> 60 | AC32: =$M32*(1+$AK$2) -> 24 | AE32: =$O32*(1+$AI$2) -> 42 | AG32: =$Q32*(1+$AK$2) -> 24 | AI32: =IF(ISBLANK(W32),VLOOKUP(A32,A32:AG32,VLOOKUP($S$1,'Price Schedule (2)'!$BA$2:$BC$6,2,FALSE),FALSE),W32) -> 35 | AK32: =IF(ISBLANK(Y32),VLOOKUP(A32,A32:AG32,VLOOKUP($S$1,'Price Schedule (2)'!$BA$2:$BC$6,3,FALSE),FALSE),Y32) -> 20 | AM32: =IF(AND(K32=0,W32=0),0,IF(K32=0,"BM is $0",(AI32-K32)/K32)) -> -0.3 | AO32: =IF(AND(M32=0,Y32=0),0,IF(M32=0,"BM is $0",(AK32-M32)/M32)) -> 0
A33: 4c Print 50lb - 60lb text, medium ink (10% - 25%) | K33: 50 | M33: 22 | O33: 35 | Q33: 22 | S33: 0 | U33: 14 | AA33: =$K33*(1+$AI$2) -> 60 | AC33: =$M33*(1+$AK$2) -> 26.4 | AE33: =$O33*(1+$AI$2) -> 42 | AG33: =$Q33*(1+$AK$2) -> 26.4 | AI33: =IF(ISBLANK(W33),VLOOKUP(A33,A33:AG33,VLOOKUP($S$1,'Price Schedule (2)'!$BA$2:$BC$6,2,FALSE),FALSE),W33) -> 35 | AK33: =IF(ISBLANK(Y33),VLOOKUP(A33,A33:AG33,VLOOKUP($S$1,'Price Schedule (2)'!$BA$2:$BC$6,3,FALSE),FALSE),Y33) -> 22 | AM33: =IF(AND(K33=0,W33=0),0,IF(K33=0,"BM is $0",(AI33-K33)/K33)) -> -0.3 | AO33: =IF(AND(M33=0,Y33=0),0,IF(M33=0,"BM is $0",(AK33-M33)/M33)) -> 0
A34: 4c Print 50lb - 60lb text, heavy ink (25% - 50%) | K34: 50 | M34: 25 | O34: 35 | Q34: 25 | S34: 0 | U34: 15 | AA34: =$K34*(1+$AI$2) -> 60 | AC34: =$M34*(1+$AK$2) -> 30 | AE34: =$O34*(1+$AI$2) -> 42 | AG34: =$Q34*(1+$AK$2) -> 30 | AI34: =IF(ISBLANK(W34),VLOOKUP(A34,A34:AG34,VLOOKUP($S$1,'Price Schedule (2)'!$BA$2:$BC$6,2,FALSE),FALSE),W34) -> 35 | AK34: =IF(ISBLANK(Y34),VLOOKUP(A34,A34:AG34,VLOOKUP($S$1,'Price Schedule (2)'!$BA$2:$BC$6,3,FALSE),FALSE),Y34) -> 25 | AM34: =IF(AND(K34=0,W34=0),0,IF(K34=0,"BM is $0",(AI34-K34)/K34)) -> -0.3 | AO34: =IF(AND(M34=0,Y34=0),0,IF(M34=0,"BM is $0",(AK34-M34)/M34)) -> 0
A35: 0c Print 70lb - 100lb text | K35: 50 | M35: 13 | O35: 35 | Q35: 13 | S35: 0 | U35: 12 | AA35: =$K35*(1+$AI$2) -> 60 | AC35: =$M35*(1+$AK$2) -> 15.6 | AE35: =$O35*(1+$AI$2) -> 42 | AG35: =$Q35*(1+$AK$2) -> 15.6 | AI35: =IF(ISBLANK(W35),VLOOKUP(A35,A35:AG35,VLOOKUP($S$1,'Price Schedule (2)'!$BA$2:$BC$6,2,FALSE),FALSE),W35) -> 35 | AK35: =IF(ISBLANK(Y35),VLOOKUP(A35,A35:AG35,VLOOKUP($S$1,'Price Schedule (2)'!$BA$2:$BC$6,3,FALSE),FALSE),Y35) -> 13 | AM35: =IF(AND(K35=0,W35=0),0,IF(K35=0,"BM is $0",(AI35-K35)/K35)) -> -0.3 | AO35: =IF(AND(M35=0,Y35=0),0,IF(M35=0,"BM is $0",(AK35-M35)/M35)) -> 0
A36: 1c Print 70lb - 100lb text, light ink (<10%) | K36: 50 | M36: 20 | O36: 35 | Q36: 20 | S36: 0 | U36: 18 | AA36: =$K36*(1+$AI$2) -> 60 | AC36: =$M36*(1+$AK$2) -> 24 | AE36: =$O36*(1+$AI$2) -> 42 | AG36: =$Q36*(1+$AK$2) -> 24 | AI36: =IF(ISBLANK(W36),VLOOKUP(A36,A36:AG36,VLOOKUP($S$1,'Price Schedule (2)'!$BA$2:$BC$6,2,FALSE),FALSE),W36) -> 35 | AK36: =IF(ISBLANK(Y36),VLOOKUP(A36,A36:AG36,VLOOKUP($S$1,'Price Schedule (2)'!$BA$2:$BC$6,3,FALSE),FALSE),Y36) -> 20 | AM36: =IF(AND(K36=0,W36=0),0,IF(K36=0,"BM is $0",(AI36-K36)/K36)) -> -0.3 | AO36: =IF(AND(M36=0,Y36=0),0,IF(M36=0,"BM is $0",(AK36-M36)/M36)) -> 0
A37: 1c Print 70lb - 100lb text, medium ink (10% - 25%) | K37: 50 | M37: 24 | O37: 35 | Q37: 24 | S37: 0 | U37: 19 | AA37: =$K37*(1+$AI$2) -> 60 | AC37: =$M37*(1+$AK$2) -> 28.8 | AE37: =$O37*(1+$AI$2) -> 42 | AG37: =$Q37*(1+$AK$2) -> 28.8 | AI37: =IF(ISBLANK(W37),VLOOKUP(A37,A37:AG37,VLOOKUP($S$1,'Price Schedule (2)'!$BA$2:$BC$6,2,FALSE),FALSE),W37) -> 35 | AK37: =IF(ISBLANK(Y37),VLOOKUP(A37,A37:AG37,VLOOKUP($S$1,'Price Schedule (2)'!$BA$2:$BC$6,3,FALSE),FALSE),Y37) -> 24 | AM37: =IF(AND(K37=0,W37=0),0,IF(K37=0,"BM is $0",(AI37-K37)/K37)) -> -0.3 | AO37: =IF(AND(M37=0,Y37=0),0,IF(M37=0,"BM is $0",(AK37-M37)/M37)) -> 0
A38: 4c Print 70lb - 100lb text, light ink (<10%) | K38: 50 | M38: 30 | O38: 35 | Q38: 30 | S38: 0 | U38: 23 | AA38: =$K38*(1+$AI$2) -> 60 | AC38: =$M38*(1+$AK$2) -> 36 | AE38: =$O38*(1+$AI$2) -> 42 | AG38: =$Q38*(1+$AK$2) -> 36 | AI38: =IF(ISBLANK(W38),VLOOKUP(A38,A38:AG38,VLOOKUP($S$1,'Price Schedule (2)'!$BA$2:$BC$6,2,FALSE),FALSE),W38) -> 35 | AK38: =IF(ISBLANK(Y38),VLOOKUP(A38,A38:AG38,VLOOKUP($S$1,'Price Schedule (2)'!$BA$2:$BC$6,3,FALSE),FALSE),Y38) -> 30 | AM38: =IF(AND(K38=0,W38=0),0,IF(K38=0,"BM is $0",(AI38-K38)/K38)) -> -0.3 | AO38: =IF(AND(M38=0,Y38=0),0,IF(M38=0,"BM is $0",(AK38-M38)/M38)) -> 0
A39: 4c Print 70lb - 100lb text, medium ink (10% - 25%) | K39: 50 | M39: 32 | O39: 35 | Q39: 32 | S39: 0 | U39: 24 | AA39: =$K39*(1+$AI$2) -> 60 | AC39: =$M39*(1+$AK$2) -> 38.4 | AE39: =$O39*(1+$AI$2) -> 42 | AG39: =$Q39*(1+$AK$2) -> 38.4 | AI39: =IF(ISBLANK(W39),VLOOKUP(A39,A39:AG39,VLOOKUP($S$1,'Price Schedule (2)'!$BA$2:$BC$6,2,FALSE),FALSE),W39) -> 35 | AK39: =IF(ISBLANK(Y39),VLOOKUP(A39,A39:AG39,VLOOKUP($S$1,'Price Schedule (2)'!$BA$2:$BC$6,3,FALSE),FALSE),Y39) -> 32 | AM39: =IF(AND(K39=0,W39=0),0,IF(K39=0,"BM is $0",(AI39-K39)/K39)) -> -0.3 | AO39: =IF(AND(M39=0,Y39=0),0,IF(M39=0,"BM is $0",(AK39-M39)/M39)) -> 0
A40: 4c Print 70lb - 100lb text, heavy ink (25% - 50%) | K40: 50 | M40: 35 | O40: 35 | Q40: 35 | S40: 0 | U40: 25 | AA40: =$K40*(1+$AI$2) -> 60 | AC40: =$M40*(1+$AK$2) -> 42 | AE40: =$O40*(1+$AI$2) -> 42 | AG40: =$Q40*(1+$AK$2) -> 42 | AI40: =IF(ISBLANK(W40),VLOOKUP(A40,A40:AG40,VLOOKUP($S$1,'Price Schedule (2)'!$BA$2:$BC$6,2,FALSE),FALSE),W40) -> 35 | AK40: =IF(ISBLANK(Y40),VLOOKUP(A40,A40:AG40,VLOOKUP($S$1,'Price Schedule (2)'!$BA$2:$BC$6,3,FALSE),FALSE),Y40) -> 35 | AM40: =IF(AND(K40=0,W40=0),0,IF(K40=0,"BM is $0",(AI40-K40)/K40)) -> -0.3 | AO40: =IF(AND(M40=0,Y40=0),0,IF(M40=0,"BM is $0",(AK40-M40)/M40)) -> 0
A41: LIQUID TONER PRESSES (Includes J-Press and F-Press)
AA53: =$K53*(1+$AI$2) -> 0 | AC53: =$M53*(1+$AK$2) -> 0 | AE53: =$O53*(1+$AI$2) -> 0 | AG53: =$Q53*(1+$AK$2) -> 0 | AI53: =IF(ISBLANK(W53),VLOOKUP(A53,A53:AG53,VLOOKUP($S$1,'Price Schedule (2)'!$BA$2:$BC$6,2,FALSE),FALSE),W53) -> 0 | AK53: =IF(ISBLANK(Y53),VLOOKUP(A53,A53:AG53,VLOOKUP($S$1,'Price Schedule (2)'!$BA$2:$BC$6,3,FALSE),FALSE),Y53) -> 0 | AM53: =IF(AND(K53=0,W53=0),0,IF(K53=0,"BM is $0",(AI53-K53)/K53)) -> 0 | AO53: =IF(AND(M53=0,Y53=0),0,IF(M53=0,"BM is $0",(AK53-M53)/M53)) -> 0
A54: OFFLINE - DIGITAL SPECIFIC | K54: MAKE-READY | M54: PER/M | O54: =K54 -> MAKE-READY | Q54: =M54 -> PER/M | S54: =K54 -> MAKE-READY | U54: =M54 -> PER/M | W54: =K54 -> MAKE-READY | Y54: =M54 -> PER/M | AA54: =K54 -> MAKE-READY | AC54: =M54 -> PER/M | AE54: =O54 -> MAKE-READY | AG54: =M54 -> PER/M | AI54: =K54 -> MAKE-READY | AK54: =M54 -> PER/M | AM54: =K54 -> MAKE-READY | AO54: =M54 -> PER/M
A55: PRESS HOLDING TIME - /Hr Inkjet | K55: 200 | M55: 0 | O55: =K55 -> 200 | Q55: =M55 -> 0 | S55: 200 | AA55: =$K55*(1+$AI$2) -> 240 | AC55: =$M55*(1+$AK$2) -> 0 | AE55: =$O55*(1+$AI$2) -> 240 | AG55: =$Q55*(1+$AK$2) -> 0 | AI55: =IF(ISBLANK(W55),VLOOKUP(A55,A55:AG55,VLOOKUP($S$1,'Price Schedule (2)'!$BA$2:$BC$6,2,FALSE),FALSE),W55) -> 200 | AK55: =IF(ISBLANK(Y55),VLOOKUP(A55,A55:AG55,VLOOKUP($S$1,'Price Schedule (2)'!$BA$2:$BC$6,3,FALSE),FALSE),Y55) -> 0 | AM55: =IF(AND(K55=0,W55=0),0,IF(K55=0,"BM is $0",(AI55-K55)/K55)) -> 0 | AO55: =IF(AND(M55=0,Y55=0),0,IF(M55=0,"BM is $0",(AK55-M55)/M55)) -> 0
A56: PRESS HOLDING TIME - /Hr Liquid Toner | K56: 350 | M56: 0 | O56: =K56 -> 350 | Q56: =M56 -> 0 | S56: 350 | AA56: =$K56*(1+$AI$2) -> 420 | AC56: =$M56*(1+$AK$2) -> 0 | AE56: =$O56*(1+$AI$2) -> 420 | AG56: =$Q56*(1+$AK$2) -> 0 | AI56: =IF(ISBLANK(W56),VLOOKUP(A56,A56:AG56,VLOOKUP($S$1,'Price Schedule (2)'!$BA$2:$BC$6,2,FALSE),FALSE),W56) -> 350 | AK56: =IF(ISBLANK(Y56),VLOOKUP(A56,A56:AG56,VLOOKUP($S$1,'Price Schedule (2)'!$BA$2:$BC$6,3,FALSE),FALSE),Y56) -> 0 | AM56: =IF(AND(K56=0,W56=0),0,IF(K56=0,"BM is $0",(AI56-K56)/K56)) -> 0 | AO56: =IF(AND(M56=0,Y56=0),0,IF(M56=0,"BM is $0",(AK56-M56)/M56)) -> 0
A57: FLOOD GLOSS UV | K57: 300 | M57: 10 | O57: =K57 -> 300 | Q57: =M57 -> 10 | AA57: =$K57*(1+$AI$2) -> 360 | AC57: =$M57*(1+$AK$2) -> 12 | AE57: =$O57*(1+$AI$2) -> 360 | AG57: =$Q57*(1+$AK$2) -> 12 | AI57: =IF(ISBLANK(W57),VLOOKUP(A57,A57:AG57,VLOOKUP($S$1,'Price Schedule (2)'!$BA$2:$BC$6,2,FALSE),FALSE),W57) -> 300 | AK57: =IF(ISBLANK(Y57),VLOOKUP(A57,A57:AG57,VLOOKUP($S$1,'Price Schedule (2)'!$BA$2:$BC$6,3,FALSE),FALSE),Y57) -> 10 | AM57: =IF(AND(K57=0,W57=0),0,IF(K57=0,"BM is $0",(AI57-K57)/K57)) -> 0 | AO57: =IF(AND(M57=0,Y57=0),0,IF(M57=0,"BM is $0",(AK57-M57)/M57)) -> 0
...
